<?xml version="1.0" encoding="utf-8"?>

<!-- This URDF was automatically created by SolidWorks to URDF Exporter! Originally created by Stephen Brawner (brawner@gmail.com) 
     Commit Version: 1.6.0-1-g15f4949  Build Version: 1.6.7594.29634
     For more information, please see http://wiki.ros.org/sw_urdf_exporter -->
<robot xmlns:xacro="http://ros.org/wiki/xacro" name="mobile_base_arm">
  <link
    name="base_link">
    <inertial>
      <origin
        xyz="0.00032177 -5.3779E-05 0.03254"
        rpy="0 0 0" />
      <mass
        value="0.31986" />
      <inertia
        ixx="0.0010346"
        ixy="-2.6698E-07"
        ixz="-5.9916E-09"
        iyy="0.0015309"
        iyz="3.0162E-08"
        izz="0.0025402" />
    </inertial>
    <visual>
      <origin
        xyz="0 0 0"
        rpy="0 0 0" />
      <geometry>
        <mesh
          filename="package://mobile_base_arm/meshes/base_link.STL" />
      </geometry>
      <material
        name="">
        <color
          rgba="0.2 0.2 0.2 1" />
      </material>
    </visual>
    <collision>
      <origin
        xyz="0 0 0"
        rpy="0 0 0" />
      <geometry>
        <mesh
          filename="package://mobile_base_arm/meshes/base_link.STL" />
      </geometry>
    </collision>
  </link>

  <xacro:include filename="$(find realsense2_description)/urdf/_d455.urdf.xacro" />
  <xacro:sensor_d455 parent="base_link" use_nominal_extrinsics="true">
    <origin xyz="0.0972160967770802 0 0.0356" rpy="0 0 0"/>
  </xacro:sensor_d455>

  <link
    name="link_1">
    <inertial>
      <origin
        xyz="0.001372 0.0064346 0.018389"
        rpy="0 0 0" />
      <mass
        value="0.068038" />
      <inertia
        ixx="4.5018E-05"
        ixy="-6.4176E-07"
        ixz="-6.2428E-06"
        iyy="5.8133E-05"
        iyz="-5.1777E-06"
        izz="5.4676E-05" />
    </inertial>
    <visual>
      <origin
        xyz="0 0 0"
        rpy="0 0 0" />
      <geometry>
        <mesh
          filename="package://mobile_base_arm/meshes/link_1.STL" />
      </geometry>
      <material
        name="">
        <color
          rgba="0.79216 0.81961 0.93333 1" />
      </material>
    </visual>
    <collision>
      <origin
        xyz="0 0 0"
        rpy="0 0 0" />
      <geometry>
        <mesh
          filename="package://mobile_base_arm/meshes/link_1.STL" />
      </geometry>
    </collision>
  </link>
  <joint
    name="joint_1"
    type="revolute">
    <origin
      xyz="0.059011 -5.5861E-05 0.0865"
      rpy="0 0 0" />
    <parent
      link="base_link" />
    <child
      link="link_1" />
    <axis
      xyz="0 0 1" />
    <limit
      lower="-2"
      upper="2"
      effort="0"
      velocity="0" />
  </joint>
  <link
    name="link_2">
    <inertial>
      <origin
        xyz="-0.023892 0.053497 0.0088688"
        rpy="0 0 0" />
      <mass
        value="0.064392" />
      <inertia
        ixx="9.0916E-05"
        ixy="3.6316E-05"
        ixz="-9.7008E-08"
        iyy="2.5232E-05"
        iyz="2.1909E-07"
        izz="0.00011184" />
    </inertial>
    <visual>
      <origin
        xyz="0 0 0"
        rpy="0 0 0" />
      <geometry>
        <mesh
          filename="package://mobile_base_arm/meshes/link_2.STL" />
      </geometry>
      <material
        name="">
        <color
          rgba="0.79216 0.81961 0.93333 1" />
      </material>
    </visual>
    <collision>
      <origin
        xyz="0 0 0"
        rpy="0 0 0" />
      <geometry>
        <mesh
          filename="package://mobile_base_arm/meshes/link_2.STL" />
      </geometry>
    </collision>
  </link>
  <joint
    name="joint_2"
    type="revolute">
    <origin
      xyz="0.0137417296065389 0.0029000000007262 0.0415532568712299"
      rpy="1.5707963267949 0 0" />
    <parent
      link="link_1" />
    <child
      link="link_2" />
    <axis
      xyz="0 0 1" />
    <limit
      lower="-1.4"
      upper="1.4"
      effort="0"
      velocity="0" />
  </joint>
  <link
    name="link_3">
    <inertial>
      <origin
        xyz="0.01964 -0.034025 0.0095089"
        rpy="0 0 0" />
      <mass
        value="0.050268" />
      <inertia
        ixx="4.3058E-05"
        ixy="1.9744E-05"
        ixz="-1.4545E-07"
        iyy="2.0829E-05"
        iyz="2.4803E-07"
        izz="5.8149E-05" />
    </inertial>
    <visual>
      <origin
        xyz="0 0 0"
        rpy="0 0 0" />
      <geometry>
        <mesh
          filename="package://mobile_base_arm/meshes/link_3.STL" />
      </geometry>
      <material
        name="">
        <color
          rgba="0.79216 0.81961 0.93333 1" />
      </material>
    </visual>
    <collision>
      <origin
        xyz="0 0 0"
        rpy="0 0 0" />
      <geometry>
        <mesh
          filename="package://mobile_base_arm/meshes/link_3.STL" />
      </geometry>
    </collision>
  </link>
  <joint
    name="joint_3"
    type="revolute">
    <origin
      xyz="-0.048691 0.10968 0"
      rpy="-3.1416 0 0" />
    <parent
      link="link_2" />
    <child
      link="link_3" />
    <axis
      xyz="0 0 -1" />
    <limit
      lower="-1.4"
      upper="1.4"
      effort="0"
      velocity="0" />
  </joint>
  <link
    name="link_4">
    <inertial>
      <origin
        xyz="-0.005046 -0.0052646 0.019341"
        rpy="0 0 0" />
      <mass
        value="0.016499" />
      <inertia
        ixx="3.9122E-06"
        ixy="3.9929E-09"
        ixz="-1.1536E-08"
        iyy="5.0224E-06"
        iyz="5.7578E-07"
        izz="2.6125E-06" />
    </inertial>
    <visual>
      <origin
        xyz="0 0 0"
        rpy="0 0 0" />
      <geometry>
        <mesh
          filename="package://mobile_base_arm/meshes/link_4.STL" />
      </geometry>
      <material
        name="">
        <color
          rgba="0.79216 0.81961 0.93333 1" />
      </material>
    </visual>
    <collision>
      <origin
        xyz="0 0 0"
        rpy="0 0 0" />
      <geometry>
        <mesh
          filename="package://mobile_base_arm/meshes/link_4.STL" />
      </geometry>
    </collision>
  </link>
  <joint
    name="joint_4"
    type="revolute">
    <origin
      xyz="0.0507079283195259 -0.0764510857051123 0.00960000000267675"
      rpy="1.57079632676818 0 0.530574095256852" />
    <parent
      link="link_3" />
    <child
      link="link_4" />
    <axis
      xyz="0 0 -1" />
    <limit
      lower="-1.4"
      upper="1.4"
      effort="0"
      velocity="0" />
  </joint>
  <link
    name="link_5">
    <inertial>
      <origin
        xyz="0.026258 -3.1222E-05 0.0095185"
        rpy="0 0 0" />
      <mass
        value="0.021182" />
      <inertia
        ixx="3.6601E-06"
        ixy="1.8735E-08"
        ixz="-9.65E-07"
        iyy="8.5553E-06"
        iyz="1.8624E-09"
        izz="9.5457E-06" />
    </inertial>
    <visual>
      <origin
        xyz="0 0 0"
        rpy="0 0 0" />
      <geometry>
        <mesh
          filename="package://mobile_base_arm/meshes/link_5.STL" />
      </geometry>
      <material
        name="">
        <color
          rgba="0.79216 0.81961 0.93333 1" />
      </material>
    </visual>
    <collision>
      <origin
        xyz="0 0 0"
        rpy="0 0 0" />
      <geometry>
        <mesh
          filename="package://mobile_base_arm/meshes/link_5.STL" />
      </geometry>
    </collision>
  </link>
  <joint
    name="joint_5"
    type="revolute">
    <origin
      xyz="-0.00499999999999984 -0.01535 0.0294999999985077"
      rpy="1.57079632682587 -0.530574095256852 0" />
    <parent
      link="link_4" />
    <child
      link="link_5" />
    <axis
      xyz="0 0 -1" />
    <limit
      lower="-1.4"
      upper="1.4"
      effort="0"
      velocity="0" />
  </joint>
  <link
    name="link_6">
    <inertial>
      <origin
        xyz="0.00068187 0.0017453 0.033787"
        rpy="0 0 0" />
      <mass
        value="0.015882" />
      <inertia
        ixx="3.2518E-06"
        ixy="-6.227E-08"
        ixz="1.5313E-08"
        iyy="2.1515E-06"
        iyz="4.4721E-08"
        izz="2.3855E-06" />
    </inertial>
    <visual>
      <origin
        xyz="0 0 0"
        rpy="0 0 0" />
      <geometry>
        <mesh
          filename="package://mobile_base_arm/meshes/link_6.STL" />
      </geometry>
      <material
        name="">
        <color
          rgba="0.79216 0.81961 0.93333 1" />
      </material>
    </visual>
    <collision>
      <origin
        xyz="0 0 0"
        rpy="0 0 0" />
      <geometry>
        <mesh
          filename="package://mobile_base_arm/meshes/link_6.STL" />
      </geometry>
    </collision>
  </link>
  <joint
    name="joint_6"
    type="revolute">
    <origin
      xyz="0.0568500000006544 0.00510000000000022 0.0123999999969983"
      rpy="-1.57079632684769 0 -1.5707963267421" />
    <parent
      link="link_5" />
    <child
      link="link_6" />
    <axis
      xyz="0 0 -1" />
    <limit
      lower="-1.4"
      upper="1.4"
      effort="0"
      velocity="0" />
  </joint>
  <link
    name="virtual_eef">
    <inertial>
      <origin
        xyz="-0.0089874 0.015289 -0.080323"
        rpy="0 0 0" />
      <mass
        value="0.0071286" />
      <inertia
        ixx="4.523E-07"
        ixy="-3.7046E-08"
        ixz="-1.4805E-09"
        iyy="3.7461E-07"
        iyz="-2.7892E-10"
        izz="6.4892E-07" />
    </inertial>
    <visual>
      <origin
        xyz="0 0 0"
        rpy="0 0 0" />
      <geometry>
        <mesh
          filename="package://mobile_base_arm/meshes/virtual_eef.STL" />
      </geometry>
      <material
        name="">
        <color
          rgba="0 0 0.8 1" />
      </material>
    </visual>
    <collision>
      <origin
        xyz="0 0 0"
        rpy="0 0 0" />
      <geometry>
        <mesh
          filename="package://mobile_base_arm/meshes/virtual_eef.STL" />
      </geometry>
    </collision>
  </link>
  <joint
    name="virtual_eef_joint"
    type="fixed">
    <origin
      xyz="-0.00175 -0.00036346 0.13185"
      rpy="0 0.0075287 -1.5708" />
    <parent
      link="link_6" />
    <child
      link="virtual_eef" />
    <axis
      xyz="0 0 0" />
  </joint>
  <link
    name="eef_link_1">
    <inertial>
      <origin
        xyz="0.00497 0.0027862 0.00415"
        rpy="0 0 0" />
      <mass
        value="0.0025659" />
      <inertia
        ixx="1.9043E-07"
        ixy="-1.3228E-07"
        ixz="1.5609E-22"
        iyy="2.6257E-07"
        iyz="5.0816E-23"
        izz="4.4616E-07" />
    </inertial>
    <visual>
      <origin
        xyz="0 0 0"
        rpy="0 0 0" />
      <geometry>
        <mesh
          filename="package://mobile_base_arm/meshes/eef_link_1.STL" />
      </geometry>
      <material
        name="">
        <color
          rgba="1 1 1 1" />
      </material>
    </visual>
    <collision>
      <origin
        xyz="0 0 0"
        rpy="0 0 0" />
      <geometry>
        <mesh
          filename="package://mobile_base_arm/meshes/eef_link_1.STL" />
      </geometry>
    </collision>
  </link>
  <joint
    name="eef_joint_1"
    type="revolute">
    <origin
      xyz="-0.013659 -0.0021 -0.080358"
      rpy="-1.5708 -1.5633 -3.1416" />
    <parent
      link="virtual_eef" />
    <child
      link="eef_link_1" />
    <axis
      xyz="0 0 1" />
    <limit
      lower="-1"
      upper="1"
      effort="0"
      velocity="0" />
  </joint>
  <link
    name="eef_finger_link_1">
    <inertial>
      <origin
        xyz="0.026471 -0.0065368 -0.00425"
        rpy="0 0 0" />
      <mass
        value="0.0053975" />
      <inertia
        ixx="1.3369E-07"
        ixy="2.5928E-07"
        ixz="-1.0206E-12"
        iyy="1.6452E-06"
        iyz="1.3992E-11"
        izz="1.7139E-06" />
    </inertial>
    <visual>
      <origin
        xyz="0 0 0"
        rpy="0 0 0" />
      <geometry>
        <mesh
          filename="package://mobile_base_arm/meshes/eef_finger_link_1.STL" />
      </geometry>
      <material
        name="">
        <color
          rgba="1 1 1 1" />
      </material>
    </visual>
    <collision>
      <origin
        xyz="0 0 0"
        rpy="0 0 0" />
      <geometry>
        <mesh
          filename="package://mobile_base_arm/meshes/eef_finger_link_1.STL" />
      </geometry>
    </collision>
  </link>
  <joint
    name="eef_finger_joint_1"
    type="revolute">
    <origin
      xyz="0.025075 0.017798 0.00215"
      rpy="0 0 0" />
    <parent
      link="eef_link_1" />
    <child
      link="eef_finger_link_1" />
    <axis
      xyz="0 0 1" />
    <limit
      lower="-1"
      upper="1"
      effort="0"
      velocity="0" />
    <mimic
      joint="eef_joint_1"
      multiplier="-0.8"
      offset="0" />
  </joint>
  <link
    name="eef_link_2">
    <inertial>
      <origin
        xyz="0.004888 -0.0027553 0.00415"
        rpy="0 0 0" />
      <mass
        value="0.0026416" />
      <inertia
        ixx="1.9158E-07"
        ixy="1.3273E-07"
        ixz="3.8346E-22"
        iyy="2.6271E-07"
        iyz="-1.6975E-22"
        izz="4.4724E-07" />
    </inertial>
    <visual>
      <origin
        xyz="0 0 0"
        rpy="0 0 0" />
      <geometry>
        <mesh
          filename="package://mobile_base_arm/meshes/eef_link_2.STL" />
      </geometry>
      <material
        name="">
        <color
          rgba="1 1 1 1" />
      </material>
    </visual>
    <collision>
      <origin
        xyz="0 0 0"
        rpy="0 0 0" />
      <geometry>
        <mesh
          filename="package://mobile_base_arm/meshes/eef_link_2.STL" />
      </geometry>
    </collision>
  </link>
  <joint
    name="eef_joint_2"
    type="revolute">
    <origin
      xyz="0.01324 -0.0021 -0.080155"
      rpy="-1.5708 -1.5633 -3.1416" />
    <parent
      link="virtual_eef" />
    <child
      link="eef_link_2" />
    <axis
      xyz="0 0 1" />
    <limit
      lower="-1"
      upper="1"
      effort="0"
      velocity="0" />
    <mimic
      joint="eef_joint_1"
      multiplier="-1"
      offset="0" />
  </joint>
  <link
    name="eef_finger_link_2">
    <inertial>
      <origin
        xyz="0.026643 0.0057965 -0.00425"
        rpy="0 0 0" />
      <mass
        value="0.0053975" />
      <inertia
        ixx="1.2042E-07"
        ixy="-2.1676E-07"
        ixz="1.4115E-12"
        iyy="1.6585E-06"
        iyz="1.3958E-11"
        izz="1.7139E-06" />
    </inertial>
    <visual>
      <origin
        xyz="0 0 0"
        rpy="0 0 0" />
      <geometry>
        <mesh
          filename="package://mobile_base_arm/meshes/eef_finger_link_2.STL" />
      </geometry>
      <material
        name="">
        <color
          rgba="1 1 1 1" />
      </material>
    </visual>
    <collision>
      <origin
        xyz="0 0 0"
        rpy="0 0 0" />
      <geometry>
        <mesh
          filename="package://mobile_base_arm/meshes/eef_finger_link_2.STL" />
      </geometry>
    </collision>
  </link>
  <joint
    name="eef_finger_joint_2"
    type="revolute">
    <origin
      xyz="0.025013 -0.017886 0.00215"
      rpy="0 0 0" />
    <parent
      link="eef_link_2" />
    <child
      link="eef_finger_link_2" />
    <axis
      xyz="0 0 1" />
    <limit
      lower="-1"
      upper="1"
      effort="0"
      velocity="0" />
    <mimic
      joint="eef_joint_2"
      multiplier="-0.8"
      offset="0" />
  </joint>
  <link
    name="lidar_link">
    <inertial>
      <origin
        xyz="0.0059879 6.8946E-07 -0.0087379"
        rpy="0 0 0" />
      <mass
        value="0.090024" />
      <inertia
        ixx="2.0425E-05"
        ixy="2.8228E-09"
        ixz="2.9686E-06"
        iyy="3.8887E-05"
        iyz="8.5101E-10"
        izz="5.2888E-05" />
    </inertial>
    <visual>
      <origin
        xyz="0 0 0"
        rpy="0 0 0" />
      <geometry>
        <mesh
          filename="package://mobile_base_arm/meshes/lidar_link.STL" />
      </geometry>
      <material
        name="">
        <color
          rgba="0 0 0.93333 1" />
      </material>
    </visual>
    <collision>
      <origin
        xyz="0 0 0"
        rpy="0 0 0" />
      <geometry>
        <mesh
          filename="package://mobile_base_arm/meshes/lidar_link.STL" />
      </geometry>
    </collision>
  </link>
  <joint
    name="lidar_joint"
    type="fixed">
    <origin
      xyz="-0.059689 -0.0002372 0.1118"
      rpy="0 0 0" />
    <parent
      link="base_link" />
    <child
      link="lidar_link" />
    <axis
      xyz="0 0 0" />
  </joint>
  <link
    name="fl_wheel">
    <inertial>
      <origin
        xyz="5.218E-15 1.4225E-15 -9.4853E-05"
        rpy="0 0 0" />
      <mass
        value="0.041913" />
      <inertia
        ixx="3.6789E-06"
        ixy="7.4838E-21"
        ixz="6.1398E-22"
        iyy="3.6789E-06"
        iyz="8.6534E-22"
        izz="3.5669E-06" />
    </inertial>
    <visual>
      <origin
        xyz="0 0 0"
        rpy="0 0 0" />
      <geometry>
        <mesh
          filename="package://mobile_base_arm/meshes/fl_wheel.STL" />
      </geometry>
      <material
        name="">
        <color
          rgba="0.75294 0.75294 0 1" />
      </material>
    </visual>
    <collision>
      <origin
        xyz="0 0 0"
        rpy="0 0 0" />
      <geometry>
        <mesh
          filename="package://mobile_base_arm/meshes/fl_wheel.STL" />
      </geometry>
    </collision>
  </link>
  <joint
    name="fl_wheel_joint"
    type="continuous">
    <origin
      xyz="0.078611 0.12644 0.011654"
      rpy="1.5708 0 -3.1416" />
    <parent
      link="base_link" />
    <child
      link="fl_wheel" />
    <axis
      xyz="0 0 1" />
  </joint>
  <link
    name="fr_wheel">
    <inertial>
      <origin
        xyz="3.3307E-16 5.5511E-17 -7.0631E-05"
        rpy="0 0 0" />
      <mass
        value="0.041913" />
      <inertia
        ixx="3.6789E-06"
        ixy="-8.5729E-21"
        ixz="-7.8275E-22"
        iyy="3.6789E-06"
        iyz="2.013E-21"
        izz="3.5671E-06" />
    </inertial>
    <visual>
      <origin
        xyz="0 0 0"
        rpy="0 0 0" />
      <geometry>
        <mesh
          filename="package://mobile_base_arm/meshes/fr_wheel.STL" />
      </geometry>
      <material
        name="">
        <color
          rgba="0.75294 0.75294 0 1" />
      </material>
    </visual>
    <collision>
      <origin
        xyz="0 0 0"
        rpy="0 0 0" />
      <geometry>
        <mesh
          filename="package://mobile_base_arm/meshes/fr_wheel.STL" />
      </geometry>
    </collision>
  </link>
  <joint
    name="fr_wheel_joint"
    type="continuous">
    <origin
      xyz="0.078611 -0.12656 0.011654"
      rpy="1.5708 0 0" />
    <parent
      link="base_link" />
    <child
      link="fr_wheel" />
    <axis
      xyz="0 0 1" />
  </joint>
  <link
    name="bl_wheel">
    <inertial>
      <origin
        xyz="1.7764E-15 4.4756E-15 9.4853E-05"
        rpy="0 0 0" />
      <mass
        value="0.041913" />
      <inertia
        ixx="3.6789E-06"
        ixy="2.4627E-21"
        ixz="-2.048E-21"
        iyy="3.6789E-06"
        iyz="-4.7401E-22"
        izz="3.5669E-06" />
    </inertial>
    <visual>
      <origin
        xyz="0 0 0"
        rpy="0 0 0" />
      <geometry>
        <mesh
          filename="package://mobile_base_arm/meshes/bl_wheel.STL" />
      </geometry>
      <material
        name="">
        <color
          rgba="0.75294 0.75294 0 1" />
      </material>
    </visual>
    <collision>
      <origin
        xyz="0 0 0"
        rpy="0 0 0" />
      <geometry>
        <mesh
          filename="package://mobile_base_arm/meshes/bl_wheel.STL" />
      </geometry>
    </collision>
  </link>
  <joint
    name="bl_wheel_joint"
    type="continuous">
    <origin
      xyz="-0.078589 0.12644 0.011654"
      rpy="1.5708 0 -3.1416" />
    <parent
      link="base_link" />
    <child
      link="bl_wheel" />
    <axis
      xyz="0 0 -1" />
  </joint>
  <link
    name="br_wheel">
    <inertial>
      <origin
        xyz="-2.2204E-16 6.9389E-17 -7.0631E-05"
        rpy="0 0 0" />
      <mass
        value="0.041913" />
      <inertia
        ixx="3.6789E-06"
        ixy="-8.8177E-21"
        ixz="-7.2196E-22"
        iyy="3.6789E-06"
        iyz="2.3484E-23"
        izz="3.5671E-06" />
    </inertial>
    <visual>
      <origin
        xyz="0 0 0"
        rpy="0 0 0" />
      <geometry>
        <mesh
          filename="package://mobile_base_arm/meshes/br_wheel.STL" />
      </geometry>
      <material
        name="">
        <color
          rgba="0.75294 0.75294 0 1" />
      </material>
    </visual>
    <collision>
      <origin
        xyz="0 0 0"
        rpy="0 0 0" />
      <geometry>
        <mesh
          filename="package://mobile_base_arm/meshes/br_wheel.STL" />
      </geometry>
    </collision>
  </link>
  <joint
    name="br_wheel_joint"
    type="continuous">
    <origin
      xyz="-0.078589 -0.12656 0.011654"
      rpy="1.5708 0 0" />
    <parent
      link="base_link" />
    <child
      link="br_wheel" />
    <axis
      xyz="0 0 1" />
  </joint>
  <!-- <link
    name="MPU9250_fl">
    <inertial>
      <origin
        xyz="0 0 -0.000785"
        rpy="0 0 0" />
      <mass
        value="0.00055422" />
      <inertia
        ixx="1.002E-08"
        ixy="1.9244E-23"
        ixz="-1.8636E-24"
        iyy="2.7776E-08"
        iyz="1.281E-24"
        izz="3.7569E-08" />
    </inertial>
    <visual>
      <origin
        xyz="0 0 0"
        rpy="0 0 0" />
      <geometry>
        <mesh
          filename="package://mobile_base_arm/meshes/MPU9250_fl.STL" />
      </geometry>
      <material
        name="">
        <color
          rgba="0 0 1 1" />
      </material>
    </visual>
    <collision>
      <origin
        xyz="0 0 0"
        rpy="0 0 0" />
      <geometry>
        <mesh
          filename="package://mobile_base_arm/meshes/MPU9250_fl.STL" />
      </geometry>
    </collision>
  </link>
  <joint
    name="MP9250_fl_joint"
    type="fixed">
    <origin
      xyz="0.082311 0.072761 0.05557"
      rpy="0 0 0" />
    <parent
      link="base_link" />
    <child
      link="MPU9250_fl" />
    <axis
      xyz="0 0 0" />
  </joint> -->
  <!-- <link
    name="MPU6050_fl">
    <inertial>
      <origin
        xyz="0 0 -0.0005715"
        rpy="0 0 0" />
      <mass
        value="0.00082747" />
      <inertia
        ixx="1.6454E-08"
        ixy="-1.306E-11"
        ixz="-1.4399E-25"
        iyy="2.9895E-08"
        iyz="2.7582E-24"
        izz="4.6169E-08" />
    </inertial>
    <visual>
      <origin
        xyz="0 0 0"
        rpy="0 0 0" />
      <geometry>
        <mesh
          filename="package://mobile_base_arm/meshes/MPU6050_fl.STL" />
      </geometry>
      <material
        name="">
        <color
          rgba="0 0 0.54902 1" />
      </material>
    </visual>
    <collision>
      <origin
        xyz="0 0 0"
        rpy="0 0 0" />
      <geometry>
        <mesh
          filename="package://mobile_base_arm/meshes/MPU6050_fl.STL" />
      </geometry>
    </collision>
  </link>
  <joint
    name="MPU6050_fl_joint"
    type="fixed">
    <origin
      xyz="0.049468 0.072059 0.055143"
      rpy="0 0 0" />
    <parent
      link="base_link" />
    <child
      link="MPU6050_fl" />
    <axis
      xyz="0 0 0" />
  </joint>
  <link
    name="MPU9250_fr">
    <inertial>
      <origin
        xyz="-1.1102E-16 0 -0.000785"
        rpy="0 0 0" />
      <mass
        value="0.00055422" />
      <inertia
        ixx="1.002E-08"
        ixy="2.878E-23"
        ixz="-1.9357E-24"
        iyy="2.7776E-08"
        iyz="1.5301E-24"
        izz="3.7569E-08" />
    </inertial>
    <visual>
      <origin
        xyz="0 0 0"
        rpy="0 0 0" />
      <geometry>
        <mesh
          filename="package://mobile_base_arm/meshes/MPU9250_fr.STL" />
      </geometry>
      <material
        name="">
        <color
          rgba="0 0 1 1" />
      </material>
    </visual>
    <collision>
      <origin
        xyz="0 0 0"
        rpy="0 0 0" />
      <geometry>
        <mesh
          filename="package://mobile_base_arm/meshes/MPU9250_fr.STL" />
      </geometry>
    </collision>
  </link>
  <joint
    name="MPU9250_fr_joint"
    type="fixed">
    <origin
      xyz="0.082211 -0.072873 0.05557"
      rpy="0 0 0" />
    <parent
      link="base_link" />
    <child
      link="MPU9250_fr" />
    <axis
      xyz="0 0 0" />
  </joint>
  <link
    name="MPU6050_fr">
    <inertial>
      <origin
        xyz="-1.1102E-16 0 -0.0005715"
        rpy="0 0 0" />
      <mass
        value="0.00082747" />
      <inertia
        ixx="1.6454E-08"
        ixy="-1.306E-11"
        ixz="-4.01E-26"
        iyy="2.9895E-08"
        iyz="3.5495E-24"
        izz="4.6169E-08" />
    </inertial>
    <visual>
      <origin
        xyz="0 0 0"
        rpy="0 0 0" />
      <geometry>
        <mesh
          filename="package://mobile_base_arm/meshes/MPU6050_fr.STL" />
      </geometry>
      <material
        name="">
        <color
          rgba="0 0 0.54902 1" />
      </material>
    </visual>
    <collision>
      <origin
        xyz="0 0 0"
        rpy="0 0 0" />
      <geometry>
        <mesh
          filename="package://mobile_base_arm/meshes/MPU6050_fr.STL" />
      </geometry>
    </collision>
  </link>
  <joint
    name="MPU6050_fr_joint"
    type="fixed">
    <origin
      xyz="0.049234 -0.072171 0.055143"
      rpy="0 0 0" />
    <parent
      link="base_link" />
    <child
      link="MPU6050_fr" />
    <axis
      xyz="0 0 0" />
  </joint>
  <link
    name="MPU9250_bl">
    <inertial>
      <origin
        xyz="0 2.7756E-17 -0.000785"
        rpy="0 0 0" />
      <mass
        value="0.00055422" />
      <inertia
        ixx="1.002E-08"
        ixy="2.2042E-23"
        ixz="-2.1684E-24"
        iyy="2.7776E-08"
        iyz="2.253E-24"
        izz="3.7569E-08" />
    </inertial>
    <visual>
      <origin
        xyz="0 0 0"
        rpy="0 0 0" />
      <geometry>
        <mesh
          filename="package://mobile_base_arm/meshes/MPU9250_bl.STL" />
      </geometry>
      <material
        name="">
        <color
          rgba="0 0 1 1" />
      </material>
    </visual>
    <collision>
      <origin
        xyz="0 0 0"
        rpy="0 0 0" />
      <geometry>
        <mesh
          filename="package://mobile_base_arm/meshes/MPU9250_bl.STL" />
      </geometry>
    </collision>
  </link>
  <joint
    name="MPU9250_bl_joint"
    type="fixed">
    <origin
      xyz="-0.082189 0.072761 0.05557"
      rpy="0 0 0" />
    <parent
      link="base_link" />
    <child
      link="MPU9250_bl" />
    <axis
      xyz="0 0 0" />
  </joint>
  <link
    name="MPU6050_bl">
    <inertial>
      <origin
        xyz="0 2.7756E-17 -0.0005715"
        rpy="0 0 0" />
      <mass
        value="0.00082747" />
      <inertia
        ixx="1.6454E-08"
        ixy="-1.306E-11"
        ixz="5.5289E-24"
        iyy="2.9895E-08"
        iyz="4.8724E-24"
        izz="4.6169E-08" />
    </inertial>
    <visual>
      <origin
        xyz="0 0 0"
        rpy="0 0 0" />
      <geometry>
        <mesh
          filename="package://mobile_base_arm/meshes/MPU6050_bl.STL" />
      </geometry>
      <material
        name="">
        <color
          rgba="0 0 0.54902 1" />
      </material>
    </visual>
    <collision>
      <origin
        xyz="0 0 0"
        rpy="0 0 0" />
      <geometry>
        <mesh
          filename="package://mobile_base_arm/meshes/MPU6050_bl.STL" />
      </geometry>
    </collision>
  </link>
  <joint
    name="MPU6050_bl_joint"
    type="fixed">
    <origin
      xyz="-0.049212 0.072059 0.055143"
      rpy="0 0 0" />
    <parent
      link="base_link" />
    <child
      link="MPU6050_bl" />
    <axis
      xyz="0 0 0" />
  </joint>
  <link
    name="MPU9250_br">
    <inertial>
      <origin
        xyz="3.3307E-16 0 -0.000785"
        rpy="0 0 0" />
      <mass
        value="0.00055422" />
      <inertia
        ixx="1.002E-08"
        ixy="1.224E-22"
        ixz="5.3526E-24"
        iyy="2.7776E-08"
        iyz="1.3295E-24"
        izz="3.7569E-08" />
    </inertial>
    <visual>
      <origin
        xyz="0 0 0"
        rpy="0 0 0" />
      <geometry>
        <mesh
          filename="package://mobile_base_arm/meshes/MPU9250_br.STL" />
      </geometry>
      <material
        name="">
        <color
          rgba="0 0 1 1" />
      </material>
    </visual>
    <collision>
      <origin
        xyz="0 0 0"
        rpy="0 0 0" />
      <geometry>
        <mesh
          filename="package://mobile_base_arm/meshes/MPU9250_br.STL" />
      </geometry>
    </collision>
  </link>
  <joint
    name="MPU9250_br_joint"
    type="fixed">
    <origin
      xyz="-0.082289 -0.072873 0.05557"
      rpy="0 0 0" />
    <parent
      link="base_link" />
    <child
      link="MPU9250_br" />
    <axis
      xyz="0 0 0" />
  </joint>
  <link
    name="MPU6050_br">
    <inertial>
      <origin
        xyz="0 3.4694E-18 -0.0005715"
        rpy="0 0 0" />
      <mass
        value="0.00082747" />
      <inertia
        ixx="1.6454E-08"
        ixy="-1.306E-11"
        ixz="1.3407E-23"
        iyy="2.9895E-08"
        iyz="-9.2717E-25"
        izz="4.6169E-08" />
    </inertial>
    <visual>
      <origin
        xyz="0 0 0"
        rpy="0 0 0" />
      <geometry>
        <mesh
          filename="package://mobile_base_arm/meshes/MPU6050_br.STL" />
      </geometry>
      <material
        name="">
        <color
          rgba="0 0 0.54902 1" />
      </material>
    </visual>
    <collision>
      <origin
        xyz="0 0 0"
        rpy="0 0 0" />
      <geometry>
        <mesh
          filename="package://mobile_base_arm/meshes/MPU6050_br.STL" />
      </geometry>
    </collision>
  </link>
  <joint
    name="MPU6050_br_joint"
    type="fixed">
    <origin
      xyz="-0.049451 -0.072171 0.055143"
      rpy="0 0 0" />
    <parent
      link="base_link" />
    <child
      link="MPU6050_br" />
    <axis
      xyz="0 0 0" />
  </joint> -->

  <!-- <link
    name="camera_link">
    <inertial>
      <origin
        xyz="0 0 0"
        rpy="0 0 0" />
      <mass
        value="0" />
      <inertia
        ixx="0"
        ixy="0"
        ixz="0"
        iyy="0"
        iyz="0"
        izz="0" />
    </inertial>
    <visual>
      <origin
        xyz="0 0 0"
        rpy="0 0 0" />
      <geometry>
        <mesh
          filename="package://mobile_base_arm/meshes/camera_link.STL" />
      </geometry>
      <material
        name="">
        <color
          rgba="0.5 0.5 0.5 1" />
      </material>
    </visual>
    <collision>
      <origin
        xyz="0 0 0"
        rpy="0 0 0" />
      <geometry>
        <mesh
          filename="package://mobile_base_arm/meshes/camera_link.STL" />
      </geometry>
    </collision>
  </link>
  <joint
    name="camera_joint"
    type="fixed">
    <origin
      xyz="0.11151 -5.5861E-05 0.012"
      rpy="0 0 0" />
    <parent
      link="base_link" />
    <child
      link="camera_link" />
    <axis
      xyz="0 0 0" />
  </joint>
  <link
    name="rpi_right">
    <inertial>
      <origin
        xyz="-0.75435 -0.0575 0.03845"
        rpy="0 0 0" />
      <mass
        value="0" />
      <inertia
        ixx="0"
        ixy="0"
        ixz="0"
        iyy="0"
        iyz="0"
        izz="0" />
    </inertial>
    <visual>
      <origin
        xyz="0 0 0"
        rpy="0 0 0" />
      <geometry>
        <mesh
          filename="package://mobile_base_arm/meshes/rpi_right.STL" />
      </geometry>
      <material
        name="">
        <color
          rgba="0 1 0 1" />
      </material>
    </visual>
    <collision>
      <origin
        xyz="0 0 0"
        rpy="0 0 0" />
      <geometry>
        <mesh
          filename="package://mobile_base_arm/meshes/rpi_right.STL" />
      </geometry>
    </collision>
  </link>
  <joint
    name="rpi_right_joint"
    type="fixed">
    <origin
      xyz="0.0056 -0.0325 0.00355"
      rpy="0 0 0" />
    <parent
      link="camera_link" />
    <child
      link="rpi_right" />
    <axis
      xyz="0 0 0" />
  </joint>
  <link
    name="rpi_right_optical">
    <inertial>
      <origin
        xyz="0.0575 -0.03845 -0.75435"
        rpy="0 0 0" />
      <mass
        value="0" />
      <inertia
        ixx="0"
        ixy="0"
        ixz="0"
        iyy="0"
        iyz="0"
        izz="0" />
    </inertial>
    <visual>
      <origin
        xyz="0 0 0"
        rpy="0 0 0" />
      <geometry>
        <mesh
          filename="package://mobile_base_arm/meshes/rpi_right_optical.STL" />
      </geometry>
      <material
        name="">
        <color
          rgba="0 1 0 1" />
      </material>
    </visual>
    <collision>
      <origin
        xyz="0 0 0"
        rpy="0 0 0" />
      <geometry>
        <mesh
          filename="package://mobile_base_arm/meshes/rpi_right_optical.STL" />
      </geometry>
    </collision>
  </link>
  <joint
    name="rpi_right_optical_joint"
    type="fixed">
    <origin
      xyz="0.0056 -0.0325 0.00355"
      rpy="-1.5708 0 -1.5708" />
    <parent
      link="camera_link" />
    <child
      link="rpi_right_optical" />
    <axis
      xyz="0 0 0" />
  </joint>
  <link
    name="rpi_left">
    <inertial>
      <origin
        xyz="-0.75435 -0.12254 0.03835"
        rpy="0 0 0" />
      <mass
        value="0" />
      <inertia
        ixx="0"
        ixy="0"
        ixz="0"
        iyy="0"
        iyz="0"
        izz="0" />
    </inertial>
    <visual>
      <origin
        xyz="0 0 0"
        rpy="0 0 0" />
      <geometry>
        <mesh
          filename="package://mobile_base_arm/meshes/rpi_left.STL" />
      </geometry>
      <material
        name="">
        <color
          rgba="0 1 0 1" />
      </material>
    </visual>
    <collision>
      <origin
        xyz="0 0 0"
        rpy="0 0 0" />
      <geometry>
        <mesh
          filename="package://mobile_base_arm/meshes/rpi_left.STL" />
      </geometry>
    </collision>
  </link>
  <joint
    name="rpi_left_joint"
    type="fixed">
    <origin
      xyz="0.005594 0.032538 0.00365"
      rpy="0 0 0" />
    <parent
      link="camera_link" />
    <child
      link="rpi_left" />
    <axis
      xyz="0 0 0" />
  </joint>
  <link
    name="rpi_left_optical">
    <inertial>
      <origin
        xyz="0.12218 -0.03835 -0.75441"
        rpy="0 0 0" />
      <mass
        value="0" />
      <inertia
        ixx="0"
        ixy="0"
        ixz="0"
        iyy="0"
        iyz="0"
        izz="0" />
    </inertial>
    <visual>
      <origin
        xyz="0 0 0"
        rpy="0 0 0" />
      <geometry>
        <mesh
          filename="package://mobile_base_arm/meshes/rpi_left_optical.STL" />
      </geometry>
      <material
        name="">
        <color
          rgba="0 1 0 1" />
      </material>
    </visual>
    <collision>
      <origin
        xyz="0 0 0"
        rpy="0 0 0" />
      <geometry>
        <mesh
          filename="package://mobile_base_arm/meshes/rpi_left_optical.STL" />
      </geometry>
    </collision>
  </link>
  <joint
    name="rpi_left_optical_joint"
    type="fixed">
    <origin
      xyz="0.005594 0.032538 0.00365"
      rpy="-1.5708 0 -1.5703" />
    <parent
      link="camera_link" />
    <child
      link="rpi_left_optical" />
    <axis
      xyz="0 0 0" />
  </joint> -->
  
</robot>