<?xml version="1.0" encoding="utf-8"?>
<!-- This URDF was automatically created by SolidWorks to URDF Exporter! Originally created by Stephen Brawner (brawner@gmail.com) 
     Commit Version: 1.6.0-1-g15f4949  Build Version: 1.6.7594.29634
     For more information, please see http://wiki.ros.org/sw_urdf_exporter -->
<robot
  name="mobile_base_arm">
  <link
    name="base_link">
    <inertial>
      <origin
        xyz="0.00032177 -5.3779E-05 0.025665"
        rpy="0 0 0" />
      <mass
        value="0.31986" />
      <inertia
        ixx="0.0010346"
        ixy="-2.6698E-07"
        ixz="-5.9916E-09"
        iyy="0.0015309"
        iyz="3.0162E-08"
        izz="0.0025402" />
    </inertial>
    <visual>
      <origin
        xyz="0 0 0"
        rpy="0 0 0" />
      <geometry>
        <mesh
          filename="package://mobile_base_arm/meshes/base_link.STL" />
      </geometry>
      <material
        name="">
        <color
          rgba="0.2 0.2 0.2 1" />
      </material>
    </visual>
    <collision>
      <origin
        xyz="0 0 0"
        rpy="0 0 0" />
      <geometry>
        <mesh
          filename="package://mobile_base_arm/meshes/base_link.STL" />
      </geometry>
    </collision>
  </link>
  <link
    name="link_1">
    <inertial>
      <origin
        xyz="0.001372 0.0064346 0.017289"
        rpy="0 0 0" />
      <mass
        value="0.068038" />
      <inertia
        ixx="4.5018E-05"
        ixy="-6.4176E-07"
        ixz="-6.2427E-06"
        iyy="5.8133E-05"
        iyz="-5.1777E-06"
        izz="5.4676E-05" />
    </inertial>
    <visual>
      <origin
        xyz="0 0 0"
        rpy="0 0 0" />
      <geometry>
        <mesh
          filename="package://mobile_base_arm/meshes/link_1.STL" />
      </geometry>
      <material
        name="">
        <color
          rgba="0.5 0.5 0.5 1" />
      </material>
    </visual>
    <collision>
      <origin
        xyz="0 0 0"
        rpy="0 0 0" />
      <geometry>
        <mesh
          filename="package://mobile_base_arm/meshes/link_1.STL" />
      </geometry>
    </collision>
  </link>
  <joint
    name="joint_1"
    type="revolute">
    <origin
      xyz="0.060511 -5.5861E-05 0.0726"
      rpy="0 0 0" />
    <parent
      link="base_link" />
    <child
      link="link_1" />
    <axis
      xyz="0 0 1" />
    <limit
      lower="-2"
      upper="2"
      effort="0"
      velocity="0" />
  </joint>
  <link
    name="link_2">
    <inertial>
      <origin
        xyz="-0.018035 0.032676 -0.0042316"
        rpy="0 0 0" />
      <mass
        value="0.098269" />
      <inertia
        ixx="9.8625E-05"
        ixy="3.4452E-05"
        ixz="-2.9438E-07"
        iyy="3.294E-05"
        iyz="2.1721E-08"
        izz="0.00011786" />
    </inertial>
    <visual>
      <origin
        xyz="0 0 0"
        rpy="0 0 0" />
      <geometry>
        <mesh
          filename="package://mobile_base_arm/meshes/link_2.STL" />
      </geometry>
      <material
        name="">
        <color
          rgba="0.5 0.5 0.5 1" />
      </material>
    </visual>
    <collision>
      <origin
        xyz="0 0 0"
        rpy="0 0 0" />
      <geometry>
        <mesh
          filename="package://mobile_base_arm/meshes/link_2.STL" />
      </geometry>
    </collision>
  </link>
  <joint
    name="joint_2"
    type="revolute">
    <origin
      xyz="0.013742 0.0018 0.040453"
      rpy="1.5708 0 0" />
    <parent
      link="link_1" />
    <child
      link="link_2" />
    <axis
      xyz="0 0 1" />
    <limit
      lower="-1.4"
      upper="1.4"
      effort="0"
      velocity="0" />
  </joint>
  <link
    name="link_3">
    <inertial>
      <origin
        xyz="0.013721 0.023715 -0.017225"
        rpy="0 0 0" />
      <mass
        value="0.084145" />
      <inertia
        ixx="5.1677E-05"
        ixy="-2.1371E-05"
        ixz="2.867E-07"
        iyy="2.7629E-05"
        iyz="4.8877E-07"
        izz="6.4165E-05" />
    </inertial>
    <visual>
      <origin
        xyz="0 0 0"
        rpy="0 0 0" />
      <geometry>
        <mesh
          filename="package://mobile_base_arm/meshes/link_3.STL" />
      </geometry>
      <material
        name="">
        <color
          rgba="0.5 0.5 0.5 1" />
      </material>
    </visual>
    <collision>
      <origin
        xyz="0 0 0"
        rpy="0 0 0" />
      <geometry>
        <mesh
          filename="package://mobile_base_arm/meshes/link_3.STL" />
      </geometry>
    </collision>
  </link>
  <joint
    name="joint_3"
    type="revolute">
    <origin
      xyz="-0.048691 0.10968 0"
      rpy="0 0 0" />
    <parent
      link="link_2" />
    <child
      link="link_3" />
    <axis
      xyz="0 0 1" />
    <limit
      lower="-1.4"
      upper="1.4"
      effort="0"
      velocity="0" />
  </joint>
  <link
    name="link_4">
    <inertial>
      <origin
        xyz="-0.004933 -0.0036763 0.0072121"
        rpy="0 0 0" />
      <mass
        value="0.023628" />
      <inertia
        ixx="4.3645E-06"
        ixy="3.9934E-09"
        ixz="-4.8582E-08"
        iyy="5.6713E-06"
        iyz="5.7578E-07"
        izz="2.9871E-06" />
    </inertial>
    <visual>
      <origin
        xyz="0 0 0"
        rpy="0 0 0" />
      <geometry>
        <mesh
          filename="package://mobile_base_arm/meshes/link_4.STL" />
      </geometry>
      <material
        name="">
        <color
          rgba="0.5 0.5 0.5 1" />
      </material>
    </visual>
    <collision>
      <origin
        xyz="0 0 0"
        rpy="0 0 0" />
      <geometry>
        <mesh
          filename="package://mobile_base_arm/meshes/link_4.STL" />
      </geometry>
    </collision>
  </link>
  <joint
    name="joint_4"
    type="revolute">
    <origin
      xyz="0.050708 0.076451 -0.0107"
      rpy="-1.5708 0 -0.53057" />
    <parent
      link="link_3" />
    <child
      link="link_4" />
    <axis
      xyz="0 0 1" />
    <limit
      lower="-1.4"
      upper="1.4"
      effort="0"
      velocity="0" />
  </joint>
  <link
    name="link_5">
    <inertial>
      <origin
        xyz="0.014865 0.0034873 -0.006785"
        rpy="0 0 0" />
      <mass
        value="0.02285" />
      <inertia
        ixx="2.932E-06"
        ixy="-1.1857E-06"
        ixz="1.4019E-06"
        iyy="8.8454E-06"
        iyz="3.0497E-07"
        izz="7.6221E-06" />
    </inertial>
    <visual>
      <origin
        xyz="0 0 0"
        rpy="0 0 0" />
      <geometry>
        <mesh
          filename="package://mobile_base_arm/meshes/link_5.STL" />
      </geometry>
      <material
        name="">
        <color
          rgba="0.5 0.5 0.5 1" />
      </material>
    </visual>
    <collision>
      <origin
        xyz="0 0 0"
        rpy="0 0 0" />
      <geometry>
        <mesh
          filename="package://mobile_base_arm/meshes/link_5.STL" />
      </geometry>
    </collision>
  </link>
  <joint
    name="joint_5"
    type="revolute">
    <origin
      xyz="-0.005 -0.01535 0.028"
      rpy="1.5708 -1.5708 0" />
    <parent
      link="link_4" />
    <child
      link="link_5" />
    <axis
      xyz="0 0 1" />
    <limit
      lower="-1.4"
      upper="1.4"
      effort="0"
      velocity="0" />
  </joint>
  <link
    name="virtual_eef">
    <inertial>
      <origin
        xyz="-0.0079571 0.015289 -0.080431"
        rpy="0 0 0" />
      <mass
        value="0.0071286" />
      <inertia
        ixx="4.5237E-07"
        ixy="-3.704E-08"
        ixz="-4.0001E-09"
        iyy="3.7461E-07"
        iyz="-7.5375E-10"
        izz="6.4885E-07" />
    </inertial>
    <visual>
      <origin
        xyz="0 0 0"
        rpy="0 0 0" />
      <geometry>
        <mesh
          filename="package://mobile_base_arm/meshes/virtual_eef.STL" />
      </geometry>
      <material
        name="">
        <color
          rgba="0 0 1 1" />
      </material>
    </visual>
    <collision>
      <origin
        xyz="0 0 0"
        rpy="0 0 0" />
      <geometry>
        <mesh
          filename="package://mobile_base_arm/meshes/virtual_eef.STL" />
      </geometry>
    </collision>
  </link>
  <joint
    name="virtual_eef_joint"
    type="fixed">
    <origin
      xyz="0.11861 0.0095012 -0.0036365"
      rpy="0 -1.5504 3.1099" />
    <parent
      link="link_5" />
    <child
      link="virtual_eef" />
    <axis
      xyz="0 0 0" />
  </joint>
  <link
    name="eef_link_1">
    <inertial>
      <origin
        xyz="-0.00497 0.0027862 -0.00415"
        rpy="0 0 0" />
      <mass
        value="0.0025659" />
      <inertia
        ixx="1.9043E-07"
        ixy="1.3228E-07"
        ixz="3.3087E-23"
        iyy="2.6257E-07"
        iyz="-1.6544E-22"
        izz="4.4616E-07" />
    </inertial>
    <visual>
      <origin
        xyz="0 0 0"
        rpy="0 0 0" />
      <geometry>
        <mesh
          filename="package://mobile_base_arm/meshes/eef_link_1.STL" />
      </geometry>
      <material
        name="">
        <color
          rgba="1 1 1 1" />
      </material>
    </visual>
    <collision>
      <origin
        xyz="0 0 0"
        rpy="0 0 0" />
      <geometry>
        <mesh
          filename="package://mobile_base_arm/meshes/eef_link_1.STL" />
      </geometry>
    </collision>
  </link>
  <joint
    name="eef_joint_1"
    type="revolute">
    <origin
      xyz="-0.012628 -0.0021 -0.080526"
      rpy="-1.5708 1.5504 0" />
    <parent
      link="virtual_eef" />
    <child
      link="eef_link_1" />
    <axis
      xyz="0 0 -1" />
    <limit
      lower="-1"
      upper="1"
      effort="0"
      velocity="0" />
  </joint>
  <link
    name="eef_finger_link_1">
    <inertial>
      <origin
        xyz="-0.026471 -0.0065368 0.00074998"
        rpy="0 0 0" />
      <mass
        value="0.0053975" />
      <inertia
        ixx="1.3369E-07"
        ixy="-2.5928E-07"
        ixz="-1.0206E-12"
        iyy="1.6452E-06"
        iyz="-1.3992E-11"
        izz="1.7139E-06" />
    </inertial>
    <visual>
      <origin
        xyz="0 0 0"
        rpy="0 0 0" />
      <geometry>
        <mesh
          filename="package://mobile_base_arm/meshes/eef_finger_link_1.STL" />
      </geometry>
      <material
        name="">
        <color
          rgba="1 1 1 1" />
      </material>
    </visual>
    <collision>
      <origin
        xyz="0 0 0"
        rpy="0 0 0" />
      <geometry>
        <mesh
          filename="package://mobile_base_arm/meshes/eef_finger_link_1.STL" />
      </geometry>
    </collision>
  </link>
  <joint
    name="eef_finger_joint_1"
    type="fixed">
    <origin
      xyz="-0.025075 0.017798 0.00135"
      rpy="0 0 0" />
    <parent
      link="eef_link_1" />
    <child
      link="eef_finger_link_1" />
    <axis
      xyz="0 0 0" />
  </joint>
  <link
    name="eef_link_2">
    <inertial>
      <origin
        xyz="-0.004888 -0.0027553 -0.00415"
        rpy="0 0 0" />
      <mass
        value="0.0026416" />
      <inertia
        ixx="1.9158E-07"
        ixy="-1.3273E-07"
        ixz="1.4558E-22"
        iyy="2.6271E-07"
        iyz="6.6174E-24"
        izz="4.4724E-07" />
    </inertial>
    <visual>
      <origin
        xyz="0 0 0"
        rpy="0 0 0" />
      <geometry>
        <mesh
          filename="package://mobile_base_arm/meshes/eef_link_2.STL" />
      </geometry>
      <material
        name="">
        <color
          rgba="1 1 1 1" />
      </material>
    </visual>
    <collision>
      <origin
        xyz="0 0 0"
        rpy="0 0 0" />
      <geometry>
        <mesh
          filename="package://mobile_base_arm/meshes/eef_link_2.STL" />
      </geometry>
    </collision>
  </link>
  <joint
    name="eef_joint_2"
    type="revolute">
    <origin
      xyz="0.014267 -0.0021 -0.079979"
      rpy="-1.5708 1.5504 0" />
    <parent
      link="virtual_eef" />
    <child
      link="eef_link_2" />
    <axis
      xyz="0 0 -1" />
    <limit
      lower="-1"
      upper="1"
      effort="0"
      velocity="0" />
    <mimic
      joint="eef_joint_1"
      multiplier="-1"
      offset="0" />
  </joint>
  <link
    name="eef_finger_link_2">
    <inertial>
      <origin
        xyz="-0.026643 0.0057965 0.00075002"
        rpy="0 0 0" />
      <mass
        value="0.0053975" />
      <inertia
        ixx="1.2042E-07"
        ixy="2.1676E-07"
        ixz="1.4115E-12"
        iyy="1.6585E-06"
        iyz="-1.3958E-11"
        izz="1.7139E-06" />
    </inertial>
    <visual>
      <origin
        xyz="0 0 0"
        rpy="0 0 0" />
      <geometry>
        <mesh
          filename="package://mobile_base_arm/meshes/eef_finger_link_2.STL" />
      </geometry>
      <material
        name="">
        <color
          rgba="1 1 1 1" />
      </material>
    </visual>
    <collision>
      <origin
        xyz="0 0 0"
        rpy="0 0 0" />
      <geometry>
        <mesh
          filename="package://mobile_base_arm/meshes/eef_finger_link_2.STL" />
      </geometry>
    </collision>
  </link>
  <joint
    name="eef_finger_joint_2"
    type="fixed">
    <origin
      xyz="-0.025013 -0.017886 0.00135"
      rpy="0 0 0" />
    <parent
      link="eef_link_2" />
    <child
      link="eef_finger_link_2" />
    <axis
      xyz="0 0 0" />
    <mimic
      joint="eef_finger_joint_1"
      multiplier="-1"
      offset="0" />
  </joint>
  <link
    name="lidar_link">
    <inertial>
      <origin
        xyz="0.0059879 6.8946E-07 -0.0087379"
        rpy="0 0 0" />
      <mass
        value="0.090024" />
      <inertia
        ixx="2.0425E-05"
        ixy="2.8228E-09"
        ixz="2.9686E-06"
        iyy="3.8887E-05"
        iyz="8.5101E-10"
        izz="5.2888E-05" />
    </inertial>
    <visual>
      <origin
        xyz="0 0 0"
        rpy="0 0 0" />
      <geometry>
        <mesh
          filename="package://mobile_base_arm/meshes/lidar_link.STL" />
      </geometry>
      <material
        name="">
        <color
          rgba="0 0 1 1" />
      </material>
    </visual>
    <collision>
      <origin
        xyz="0 0 0"
        rpy="0 0 0" />
      <geometry>
        <mesh
          filename="package://mobile_base_arm/meshes/lidar_link.STL" />
      </geometry>
    </collision>
  </link>
  <joint
    name="lidar_joint"
    type="fixed">
    <origin
      xyz="-0.059689 -0.0002372 0.0968"
      rpy="0 0 0" />
    <parent
      link="base_link" />
    <child
      link="lidar_link" />
    <axis
      xyz="0 0 0" />
  </joint>
  <link
    name="fl_wheel">
    <inertial>
      <origin
        xyz="4.774E-15 1.4086E-15 -9.4853E-05"
        rpy="0 0 0" />
      <mass
        value="0.041913" />
      <inertia
        ixx="3.6789E-06"
        ixy="7.4707E-21"
        ixz="6.0006E-22"
        iyy="3.6789E-06"
        iyz="8.6318E-22"
        izz="3.5669E-06" />
    </inertial>
    <visual>
      <origin
        xyz="0 0 0"
        rpy="0 0 0" />
      <geometry>
        <mesh
          filename="package://mobile_base_arm/meshes/fl_wheel.STL" />
      </geometry>
      <material
        name="">
        <color
          rgba="1 1 0 1" />
      </material>
    </visual>
    <collision>
      <origin
        xyz="0 0 0"
        rpy="0 0 0" />
      <geometry>
        <mesh
          filename="package://mobile_base_arm/meshes/fl_wheel.STL" />
      </geometry>
    </collision>
  </link>
  <joint
    name="fl_wheel_joint"
    type="continuous">
    <origin
      xyz="0.078611 0.12644 0.011654"
      rpy="1.5708 0 -3.1416" />
    <parent
      link="base_link" />
    <child
      link="fl_wheel" />
    <axis
      xyz="0 0 1" />
  </joint>
  <link
    name="fr_wheel">
    <inertial>
      <origin
        xyz="-2.2204E-16 6.9389E-17 -7.0631E-05"
        rpy="0 0 0" />
      <mass
        value="0.041913" />
      <inertia
        ixx="3.6789E-06"
        ixy="-8.5464E-21"
        ixz="-7.6289E-22"
        iyy="3.6789E-06"
        iyz="1.9898E-21"
        izz="3.5671E-06" />
    </inertial>
    <visual>
      <origin
        xyz="0 0 0"
        rpy="0 0 0" />
      <geometry>
        <mesh
          filename="package://mobile_base_arm/meshes/fr_wheel.STL" />
      </geometry>
      <material
        name="">
        <color
          rgba="1 1 0 1" />
      </material>
    </visual>
    <collision>
      <origin
        xyz="0 0 0"
        rpy="0 0 0" />
      <geometry>
        <mesh
          filename="package://mobile_base_arm/meshes/fr_wheel.STL" />
      </geometry>
    </collision>
  </link>
  <joint
    name="fr_wheel_joint"
    type="continuous">
    <origin
      xyz="0.078611 -0.12656 0.011654"
      rpy="1.5708 0 0" />
    <parent
      link="base_link" />
    <child
      link="fr_wheel" />
    <axis
      xyz="0 0 1" />
  </joint>
  <link
    name="bl_wheel">
    <inertial>
      <origin
        xyz="2.6645E-15 4.4964E-15 9.4853E-05"
        rpy="0 0 0" />
      <mass
        value="0.041913" />
      <inertia
        ixx="3.6789E-06"
        ixy="2.4773E-21"
        ixz="-2.0786E-21"
        iyy="3.6789E-06"
        iyz="-4.5776E-22"
        izz="3.5669E-06" />
    </inertial>
    <visual>
      <origin
        xyz="0 0 0"
        rpy="0 0 0" />
      <geometry>
        <mesh
          filename="package://mobile_base_arm/meshes/bl_wheel.STL" />
      </geometry>
      <material
        name="">
        <color
          rgba="1 1 0 1" />
      </material>
    </visual>
    <collision>
      <origin
        xyz="0 0 0"
        rpy="0 0 0" />
      <geometry>
        <mesh
          filename="package://mobile_base_arm/meshes/bl_wheel.STL" />
      </geometry>
    </collision>
  </link>
  <joint
    name="bl_wheel_joint"
    type="continuous">
    <origin
      xyz="-0.078589 0.12644 0.011654"
      rpy="1.5708 0 -3.1416" />
    <parent
      link="base_link" />
    <child
      link="bl_wheel" />
    <axis
      xyz="0 0 -1" />
  </joint>
  <link
    name="br_wheel">
    <inertial>
      <origin
        xyz="-5.5511E-16 9.0206E-17 -7.0631E-05"
        rpy="0 0 0" />
      <mass
        value="0.041913" />
      <inertia
        ixx="3.6789E-06"
        ixy="-8.8144E-21"
        ixz="-7.2527E-22"
        iyy="3.6789E-06"
        iyz="3.6719E-23"
        izz="3.5671E-06" />
    </inertial>
    <visual>
      <origin
        xyz="0 0 0"
        rpy="0 0 0" />
      <geometry>
        <mesh
          filename="package://mobile_base_arm/meshes/br_wheel.STL" />
      </geometry>
      <material
        name="">
        <color
          rgba="1 1 0 1" />
      </material>
    </visual>
    <collision>
      <origin
        xyz="0 0 0"
        rpy="0 0 0" />
      <geometry>
        <mesh
          filename="package://mobile_base_arm/meshes/br_wheel.STL" />
      </geometry>
    </collision>
  </link>
  <joint
    name="br_wheel_joint"
    type="continuous">
    <origin
      xyz="-0.078589 -0.12656 0.011654"
      rpy="1.5708 0 0" />
    <parent
      link="base_link" />
    <child
      link="br_wheel" />
    <axis
      xyz="0 0 1" />
  </joint>
  <link
    name="MPU9250_fl">
    <inertial>
      <origin
        xyz="0 0 -0.000785"
        rpy="0 0 0" />
      <mass
        value="0.00055422" />
      <inertia
        ixx="1.002E-08"
        ixy="1.9244E-23"
        ixz="-1.8636E-24"
        iyy="2.7776E-08"
        iyz="1.281E-24"
        izz="3.7569E-08" />
    </inertial>
    <visual>
      <origin
        xyz="0 0 0"
        rpy="0 0 0" />
      <geometry>
        <mesh
          filename="package://mobile_base_arm/meshes/MPU9250_fl.STL" />
      </geometry>
      <material
        name="">
        <color
          rgba="0 0 1 1" />
      </material>
    </visual>
    <collision>
      <origin
        xyz="0 0 0"
        rpy="0 0 0" />
      <geometry>
        <mesh
          filename="package://mobile_base_arm/meshes/MPU9250_fl.STL" />
      </geometry>
    </collision>
  </link>
  <joint
    name="MP9250_fl_joint"
    type="fixed">
    <origin
      xyz="0.082311 0.072761 0.05557"
      rpy="0 0 0" />
    <parent
      link="base_link" />
    <child
      link="MPU9250_fl" />
    <axis
      xyz="0 0 0" />
  </joint>
  <!-- <link
    name="MPU6050_fl">
    <inertial>
      <origin
        xyz="0 0 -0.0005715"
        rpy="0 0 0" />
      <mass
        value="0.00082747" />
      <inertia
        ixx="1.6454E-08"
        ixy="-1.306E-11"
        ixz="-1.4399E-25"
        iyy="2.9895E-08"
        iyz="2.7582E-24"
        izz="4.6169E-08" />
    </inertial>
    <visual>
      <origin
        xyz="0 0 0"
        rpy="0 0 0" />
      <geometry>
        <mesh
          filename="package://mobile_base_arm/meshes/MPU6050_fl.STL" />
      </geometry>
      <material
        name="">
        <color
          rgba="0 0 0.54902 1" />
      </material>
    </visual>
    <collision>
      <origin
        xyz="0 0 0"
        rpy="0 0 0" />
      <geometry>
        <mesh
          filename="package://mobile_base_arm/meshes/MPU6050_fl.STL" />
      </geometry>
    </collision>
  </link>
  <joint
    name="MPU6050_fl_joint"
    type="fixed">
    <origin
      xyz="0.049468 0.072059 0.055143"
      rpy="0 0 0" />
    <parent
      link="base_link" />
    <child
      link="MPU6050_fl" />
    <axis
      xyz="0 0 0" />
  </joint>
  <link
    name="MPU9250_fr">
    <inertial>
      <origin
        xyz="-1.1102E-16 0 -0.000785"
        rpy="0 0 0" />
      <mass
        value="0.00055422" />
      <inertia
        ixx="1.002E-08"
        ixy="2.878E-23"
        ixz="-1.9357E-24"
        iyy="2.7776E-08"
        iyz="1.5301E-24"
        izz="3.7569E-08" />
    </inertial>
    <visual>
      <origin
        xyz="0 0 0"
        rpy="0 0 0" />
      <geometry>
        <mesh
          filename="package://mobile_base_arm/meshes/MPU9250_fr.STL" />
      </geometry>
      <material
        name="">
        <color
          rgba="0 0 1 1" />
      </material>
    </visual>
    <collision>
      <origin
        xyz="0 0 0"
        rpy="0 0 0" />
      <geometry>
        <mesh
          filename="package://mobile_base_arm/meshes/MPU9250_fr.STL" />
      </geometry>
    </collision>
  </link>
  <joint
    name="MPU9250_fr_joint"
    type="fixed">
    <origin
      xyz="0.082211 -0.072873 0.05557"
      rpy="0 0 0" />
    <parent
      link="base_link" />
    <child
      link="MPU9250_fr" />
    <axis
      xyz="0 0 0" />
  </joint>
  <link
    name="MPU6050_fr">
    <inertial>
      <origin
        xyz="-1.1102E-16 0 -0.0005715"
        rpy="0 0 0" />
      <mass
        value="0.00082747" />
      <inertia
        ixx="1.6454E-08"
        ixy="-1.306E-11"
        ixz="-4.01E-26"
        iyy="2.9895E-08"
        iyz="3.5495E-24"
        izz="4.6169E-08" />
    </inertial>
    <visual>
      <origin
        xyz="0 0 0"
        rpy="0 0 0" />
      <geometry>
        <mesh
          filename="package://mobile_base_arm/meshes/MPU6050_fr.STL" />
      </geometry>
      <material
        name="">
        <color
          rgba="0 0 0.54902 1" />
      </material>
    </visual>
    <collision>
      <origin
        xyz="0 0 0"
        rpy="0 0 0" />
      <geometry>
        <mesh
          filename="package://mobile_base_arm/meshes/MPU6050_fr.STL" />
      </geometry>
    </collision>
  </link>
  <joint
    name="MPU6050_fr_joint"
    type="fixed">
    <origin
      xyz="0.049234 -0.072171 0.055143"
      rpy="0 0 0" />
    <parent
      link="base_link" />
    <child
      link="MPU6050_fr" />
    <axis
      xyz="0 0 0" />
  </joint>
  <link
    name="MPU9250_bl">
    <inertial>
      <origin
        xyz="0 2.7756E-17 -0.000785"
        rpy="0 0 0" />
      <mass
        value="0.00055422" />
      <inertia
        ixx="1.002E-08"
        ixy="2.2042E-23"
        ixz="-2.1684E-24"
        iyy="2.7776E-08"
        iyz="2.253E-24"
        izz="3.7569E-08" />
    </inertial>
    <visual>
      <origin
        xyz="0 0 0"
        rpy="0 0 0" />
      <geometry>
        <mesh
          filename="package://mobile_base_arm/meshes/MPU9250_bl.STL" />
      </geometry>
      <material
        name="">
        <color
          rgba="0 0 1 1" />
      </material>
    </visual>
    <collision>
      <origin
        xyz="0 0 0"
        rpy="0 0 0" />
      <geometry>
        <mesh
          filename="package://mobile_base_arm/meshes/MPU9250_bl.STL" />
      </geometry>
    </collision>
  </link>
  <joint
    name="MPU9250_bl_joint"
    type="fixed">
    <origin
      xyz="-0.082189 0.072761 0.05557"
      rpy="0 0 0" />
    <parent
      link="base_link" />
    <child
      link="MPU9250_bl" />
    <axis
      xyz="0 0 0" />
  </joint>
  <link
    name="MPU6050_bl">
    <inertial>
      <origin
        xyz="0 2.7756E-17 -0.0005715"
        rpy="0 0 0" />
      <mass
        value="0.00082747" />
      <inertia
        ixx="1.6454E-08"
        ixy="-1.306E-11"
        ixz="5.5289E-24"
        iyy="2.9895E-08"
        iyz="4.8724E-24"
        izz="4.6169E-08" />
    </inertial>
    <visual>
      <origin
        xyz="0 0 0"
        rpy="0 0 0" />
      <geometry>
        <mesh
          filename="package://mobile_base_arm/meshes/MPU6050_bl.STL" />
      </geometry>
      <material
        name="">
        <color
          rgba="0 0 0.54902 1" />
      </material>
    </visual>
    <collision>
      <origin
        xyz="0 0 0"
        rpy="0 0 0" />
      <geometry>
        <mesh
          filename="package://mobile_base_arm/meshes/MPU6050_bl.STL" />
      </geometry>
    </collision>
  </link>
  <joint
    name="MPU6050_bl_joint"
    type="fixed">
    <origin
      xyz="-0.049212 0.072059 0.055143"
      rpy="0 0 0" />
    <parent
      link="base_link" />
    <child
      link="MPU6050_bl" />
    <axis
      xyz="0 0 0" />
  </joint>
  <link
    name="MPU9250_br">
    <inertial>
      <origin
        xyz="3.3307E-16 0 -0.000785"
        rpy="0 0 0" />
      <mass
        value="0.00055422" />
      <inertia
        ixx="1.002E-08"
        ixy="1.224E-22"
        ixz="5.3526E-24"
        iyy="2.7776E-08"
        iyz="1.3295E-24"
        izz="3.7569E-08" />
    </inertial>
    <visual>
      <origin
        xyz="0 0 0"
        rpy="0 0 0" />
      <geometry>
        <mesh
          filename="package://mobile_base_arm/meshes/MPU9250_br.STL" />
      </geometry>
      <material
        name="">
        <color
          rgba="0 0 1 1" />
      </material>
    </visual>
    <collision>
      <origin
        xyz="0 0 0"
        rpy="0 0 0" />
      <geometry>
        <mesh
          filename="package://mobile_base_arm/meshes/MPU9250_br.STL" />
      </geometry>
    </collision>
  </link>
  <joint
    name="MPU9250_br_joint"
    type="fixed">
    <origin
      xyz="-0.082289 -0.072873 0.05557"
      rpy="0 0 0" />
    <parent
      link="base_link" />
    <child
      link="MPU9250_br" />
    <axis
      xyz="0 0 0" />
  </joint>
  <link
    name="MPU6050_br">
    <inertial>
      <origin
        xyz="0 3.4694E-18 -0.0005715"
        rpy="0 0 0" />
      <mass
        value="0.00082747" />
      <inertia
        ixx="1.6454E-08"
        ixy="-1.306E-11"
        ixz="1.3407E-23"
        iyy="2.9895E-08"
        iyz="-9.2717E-25"
        izz="4.6169E-08" />
    </inertial>
    <visual>
      <origin
        xyz="0 0 0"
        rpy="0 0 0" />
      <geometry>
        <mesh
          filename="package://mobile_base_arm/meshes/MPU6050_br.STL" />
      </geometry>
      <material
        name="">
        <color
          rgba="0 0 0.54902 1" />
      </material>
    </visual>
    <collision>
      <origin
        xyz="0 0 0"
        rpy="0 0 0" />
      <geometry>
        <mesh
          filename="package://mobile_base_arm/meshes/MPU6050_br.STL" />
      </geometry>
    </collision>
  </link>
  <joint
    name="MPU6050_br_joint"
    type="fixed">
    <origin
      xyz="-0.049451 -0.072171 0.055143"
      rpy="0 0 0" />
    <parent
      link="base_link" />
    <child
      link="MPU6050_br" />
    <axis
      xyz="0 0 0" />
  </joint> -->
  <link
    name="camera_link">
    <inertial>
      <origin
        xyz="0 0 0"
        rpy="0 0 0" />
      <mass
        value="0" />
      <inertia
        ixx="0"
        ixy="0"
        ixz="0"
        iyy="0"
        iyz="0"
        izz="0" />
    </inertial>
    <visual>
      <origin
        xyz="0 0 0"
        rpy="0 0 0" />
      <geometry>
        <mesh
          filename="package://mobile_base_arm/meshes/camera_link.STL" />
      </geometry>
      <material
        name="">
        <color
          rgba="0.5 0.5 0.5 1" />
      </material>
    </visual>
    <collision>
      <origin
        xyz="0 0 0"
        rpy="0 0 0" />
      <geometry>
        <mesh
          filename="package://mobile_base_arm/meshes/camera_link.STL" />
      </geometry>
    </collision>
  </link>
  <joint
    name="camera_joint"
    type="fixed">
    <origin
      xyz="0.11151 -5.5861E-05 0.012"
      rpy="0 0 0" />
    <parent
      link="base_link" />
    <child
      link="camera_link" />
    <axis
      xyz="0 0 0" />
  </joint>
  <link
    name="rpi_right">
    <inertial>
      <origin
        xyz="-0.75435 -0.0575 0.03845"
        rpy="0 0 0" />
      <mass
        value="0" />
      <inertia
        ixx="0"
        ixy="0"
        ixz="0"
        iyy="0"
        iyz="0"
        izz="0" />
    </inertial>
    <visual>
      <origin
        xyz="0 0 0"
        rpy="0 0 0" />
      <geometry>
        <mesh
          filename="package://mobile_base_arm/meshes/rpi_right.STL" />
      </geometry>
      <material
        name="">
        <color
          rgba="0 1 0 1" />
      </material>
    </visual>
    <collision>
      <origin
        xyz="0 0 0"
        rpy="0 0 0" />
      <geometry>
        <mesh
          filename="package://mobile_base_arm/meshes/rpi_right.STL" />
      </geometry>
    </collision>
  </link>
  <joint
    name="rpi_right_joint"
    type="fixed">
    <origin
      xyz="0.0056 -0.0325 0.00355"
      rpy="0 0 0" />
    <parent
      link="camera_link" />
    <child
      link="rpi_right" />
    <axis
      xyz="0 0 0" />
  </joint>
  <link
    name="rpi_right_optical">
    <inertial>
      <origin
        xyz="0.0575 -0.03845 -0.75435"
        rpy="0 0 0" />
      <mass
        value="0" />
      <inertia
        ixx="0"
        ixy="0"
        ixz="0"
        iyy="0"
        iyz="0"
        izz="0" />
    </inertial>
    <visual>
      <origin
        xyz="0 0 0"
        rpy="0 0 0" />
      <geometry>
        <mesh
          filename="package://mobile_base_arm/meshes/rpi_right_optical.STL" />
      </geometry>
      <material
        name="">
        <color
          rgba="0 1 0 1" />
      </material>
    </visual>
    <collision>
      <origin
        xyz="0 0 0"
        rpy="0 0 0" />
      <geometry>
        <mesh
          filename="package://mobile_base_arm/meshes/rpi_right_optical.STL" />
      </geometry>
    </collision>
  </link>
  <joint
    name="rpi_right_optical_joint"
    type="fixed">
    <origin
      xyz="0.0056 -0.0325 0.00355"
      rpy="-1.5708 0 -1.5708" />
    <parent
      link="camera_link" />
    <child
      link="rpi_right_optical" />
    <axis
      xyz="0 0 0" />
  </joint>
  <link
    name="rpi_left">
    <inertial>
      <origin
        xyz="-0.75435 -0.12254 0.03835"
        rpy="0 0 0" />
      <mass
        value="0" />
      <inertia
        ixx="0"
        ixy="0"
        ixz="0"
        iyy="0"
        iyz="0"
        izz="0" />
    </inertial>
    <visual>
      <origin
        xyz="0 0 0"
        rpy="0 0 0" />
      <geometry>
        <mesh
          filename="package://mobile_base_arm/meshes/rpi_left.STL" />
      </geometry>
      <material
        name="">
        <color
          rgba="0 1 0 1" />
      </material>
    </visual>
    <collision>
      <origin
        xyz="0 0 0"
        rpy="0 0 0" />
      <geometry>
        <mesh
          filename="package://mobile_base_arm/meshes/rpi_left.STL" />
      </geometry>
    </collision>
  </link>
  <joint
    name="rpi_left_joint"
    type="fixed">
    <origin
      xyz="0.005594 0.032538 0.00365"
      rpy="0 0 0" />
    <parent
      link="camera_link" />
    <child
      link="rpi_left" />
    <axis
      xyz="0 0 0" />
  </joint>
  <link
    name="rpi_left_optical">
    <inertial>
      <origin
        xyz="0.12218 -0.03835 -0.75441"
        rpy="0 0 0" />
      <mass
        value="0" />
      <inertia
        ixx="0"
        ixy="0"
        ixz="0"
        iyy="0"
        iyz="0"
        izz="0" />
    </inertial>
    <visual>
      <origin
        xyz="0 0 0"
        rpy="0 0 0" />
      <geometry>
        <mesh
          filename="package://mobile_base_arm/meshes/rpi_left_optical.STL" />
      </geometry>
      <material
        name="">
        <color
          rgba="0 1 0 1" />
      </material>
    </visual>
    <collision>
      <origin
        xyz="0 0 0"
        rpy="0 0 0" />
      <geometry>
        <mesh
          filename="package://mobile_base_arm/meshes/rpi_left_optical.STL" />
      </geometry>
    </collision>
  </link>
  <joint
    name="rpi_left_optical_joint"
    type="fixed">
    <origin
      xyz="0.005594 0.032538 0.00365"
      rpy="-1.5708 0 -1.5703" />
    <parent
      link="camera_link" />
    <child
      link="rpi_left_optical" />
    <axis
      xyz="0 0 0" />
  </joint>
</robot>